2023-03-17 12:16:28,214 | ERROR | Internal Server Error: /accounts/login/ | C:\Users\Altf4\AppData\Local\Programs\Python\Python311\Lib\site-packages\django\utils\log.py | (<class 'smtplib.SMTPAuthenticationError'>, SMTPAuthenticationError(535, b'5.7.8 Error: authentication failed: This user does not have access rights to this service 1679044586-QGhFp86DZa60'), <traceback object at 0x00000258D3EA8E00>)
Traceback (most recent call last):
  File "C:\Users\Altf4\AppData\Local\Programs\Python\Python311\Lib\site-packages\django\core\handlers\exception.py", line 55, in inner
    response = get_response(request)
               ^^^^^^^^^^^^^^^^^^^^^
  File "C:\Users\Altf4\AppData\Local\Programs\Python\Python311\Lib\site-packages\django\core\handlers\base.py", line 197, in _get_response
    response = wrapped_callback(request, *callback_args, **callback_kwargs)
               ^^^^^^^^^^^^^^^^^^^^^^^^^^^^^^^^^^^^^^^^^^^^^^^^^^^^^^^^^^^^
  File "C:\Users\Altf4\AppData\Local\Programs\Python\Python311\Lib\site-packages\django\views\generic\base.py", line 103, in view
    return self.dispatch(request, *args, **kwargs)
           ^^^^^^^^^^^^^^^^^^^^^^^^^^^^^^^^^^^^^^^
  File "C:\Users\Altf4\AppData\Local\Programs\Python\Python311\Lib\site-packages\django\utils\decorators.py", line 46, in _wrapper
    return bound_method(*args, **kwargs)
           ^^^^^^^^^^^^^^^^^^^^^^^^^^^^^
  File "C:\Users\Altf4\AppData\Local\Programs\Python\Python311\Lib\site-packages\django\views\decorators\debug.py", line 92, in sensitive_post_parameters_wrapper
    return view(request, *args, **kwargs)
           ^^^^^^^^^^^^^^^^^^^^^^^^^^^^^^
  File "C:\Users\Altf4\AppData\Local\Programs\Python\Python311\Lib\site-packages\allauth\account\views.py", line 149, in dispatch
    return super(LoginView, self).dispatch(request, *args, **kwargs)
           ^^^^^^^^^^^^^^^^^^^^^^^^^^^^^^^^^^^^^^^^^^^^^^^^^^^^^^^^^
  File "C:\Users\Altf4\AppData\Local\Programs\Python\Python311\Lib\site-packages\allauth\account\views.py", line 77, in dispatch
    response = super(RedirectAuthenticatedUserMixin, self).dispatch(
               ^^^^^^^^^^^^^^^^^^^^^^^^^^^^^^^^^^^^^^^^^^^^^^^^^^^^^
  File "C:\Users\Altf4\AppData\Local\Programs\Python\Python311\Lib\site-packages\django\views\generic\base.py", line 142, in dispatch
    return handler(request, *args, **kwargs)
           ^^^^^^^^^^^^^^^^^^^^^^^^^^^^^^^^^
  File "C:\Users\Altf4\AppData\Local\Programs\Python\Python311\Lib\site-packages\allauth\account\views.py", line 105, in post
    response = self.form_valid(form)
               ^^^^^^^^^^^^^^^^^^^^^
  File "C:\Users\Altf4\AppData\Local\Programs\Python\Python311\Lib\site-packages\allauth\account\views.py", line 162, in form_valid
    return form.login(self.request, redirect_url=success_url)
           ^^^^^^^^^^^^^^^^^^^^^^^^^^^^^^^^^^^^^^^^^^^^^^^^^^
  File "C:\Users\Altf4\AppData\Local\Programs\Python\Python311\Lib\site-packages\allauth\account\forms.py", line 196, in login
    ret = perform_login(
          ^^^^^^^^^^^^^^
  File "C:\Users\Altf4\AppData\Local\Programs\Python\Python311\Lib\site-packages\allauth\account\utils.py", line 168, in perform_login
    response = adapter.pre_login(request, user, **hook_kwargs)
               ^^^^^^^^^^^^^^^^^^^^^^^^^^^^^^^^^^^^^^^^^^^^^^^
  File "C:\Users\Altf4\AppData\Local\Programs\Python\Python311\Lib\site-packages\allauth\account\adapter.py", line 412, in pre_login
    send_email_confirmation(request, user, signup=signup, email=email)
  File "C:\Users\Altf4\AppData\Local\Programs\Python\Python311\Lib\site-packages\allauth\account\utils.py", line 319, in send_email_confirmation
    email_address.send_confirmation(request, signup=signup)
  File "C:\Users\Altf4\AppData\Local\Programs\Python\Python311\Lib\site-packages\allauth\account\models.py", line 59, in send_confirmation
    confirmation.send(request, signup=signup)
  File "C:\Users\Altf4\AppData\Local\Programs\Python\Python311\Lib\site-packages\allauth\account\models.py", line 166, in send
    get_adapter(request).send_confirmation_mail(request, self, signup)
  File "C:\Users\Altf4\AppData\Local\Programs\Python\Python311\Lib\site-packages\allauth\account\adapter.py", line 549, in send_confirmation_mail
    self.send_mail(email_template, emailconfirmation.email_address.email, ctx)
  File "C:\Users\Altf4\AppData\Local\Programs\Python\Python311\Lib\site-packages\allauth\account\adapter.py", line 140, in send_mail
    msg.send()
  File "C:\Users\Altf4\AppData\Local\Programs\Python\Python311\Lib\site-packages\django\core\mail\message.py", line 298, in send
    return self.get_connection(fail_silently).send_messages([self])
           ^^^^^^^^^^^^^^^^^^^^^^^^^^^^^^^^^^^^^^^^^^^^^^^^^^^^^^^^
  File "C:\Users\Altf4\AppData\Local\Programs\Python\Python311\Lib\site-packages\django\core\mail\backends\smtp.py", line 124, in send_messages
    new_conn_created = self.open()
                       ^^^^^^^^^^^
  File "C:\Users\Altf4\AppData\Local\Programs\Python\Python311\Lib\site-packages\django\core\mail\backends\smtp.py", line 91, in open
    self.connection.login(self.username, self.password)
  File "C:\Users\Altf4\AppData\Local\Programs\Python\Python311\Lib\smtplib.py", line 750, in login
    raise last_exception
  File "C:\Users\Altf4\AppData\Local\Programs\Python\Python311\Lib\smtplib.py", line 739, in login
    (code, resp) = self.auth(
                   ^^^^^^^^^^
  File "C:\Users\Altf4\AppData\Local\Programs\Python\Python311\Lib\smtplib.py", line 662, in auth
    raise SMTPAuthenticationError(code, resp)
smtplib.SMTPAuthenticationError: (535, b'5.7.8 Error: authentication failed: This user does not have access rights to this service 1679044586-QGhFp86DZa60')
2023-03-17 12:16:28,222 | ERROR | "POST /accounts/login/ HTTP/1.1" 500 171657 | C:\Users\Altf4\AppData\Local\Programs\Python\Python311\Lib\site-packages\django\core\servers\basehttp.py | None
